Workbook

Sheet 合同 
A1: 销 售 合 同 SALES CONTRACT
A3: 卖方（The sellers): | C3: 深圳兴协贸易有限公司 | E3: 合同编号（ Contract No.）： | G3: =装箱单!K9 -> 0
A4: 地址（Address): | C4: 深圳市南山区西丽街道麻磡社区奇星工业园5号整套 | E4: 日期（Date）: | G4: =装箱单!K7 -> 0
A5: 电话/传真（Tel/Fax): | C5: 13202273056 | E5: 签订地点（Signed at）: | G5: 深圳
A7: 买方（The buyer): | C7: 俊興貿易公司
A8: 地址（Address): | C8: 新蒲崗大有街3號萬迪廣場12樓E室
A9: 电话/传真（Tel/Fax): | C9: 63381808
A11: 兹经买卖双方同意按照以下条款和条件买卖下述产品：
A12: The seller hereby agrees to sell the buyer and buyer agrees to buy from the seller the under mentioned commodities subject to the terms and conditions set forth hereinafter as follower:
A14: stipulated below:
A15: （1）商品
A16: 货物名称、型号 | B16: 品牌 | C16: 数量(KG) | D16: 单价(RMB) | E16: 金额 (RMB)
A17: Description of Commodity、 Model | B17: BRAND | C17: QUANTITY | D17: U.PRICE | E17: AMOUNT
A18: =IF(发票!A9=0,"",发票!A9) | B18: =IF(发票!B9=0,"",发票!B9) | C18: =IF(发票!C9=0,"",发票!C9) | D18: =IF(发票!D9=0,"",发票!D9) -> #DIV/0! | E18: =IF(发票!E9=0,"",发票!E9)
A19: =IF(发票!A10=0,"",发票!A10) | B19: =IF(发票!B10=0,"",发票!B10) | C19: =IF(发票!C10=0,"",发票!C10) | D19: =IF(发票!D10=0,"",发票!D10) -> #DIV/0! | E19: =IF(发票!E10=0,"",发票!E10)
A20: =IF(发票!A11=0,"",发票!A11) | B20: =IF(发票!B11=0,"",发票!B11) | C20: =IF(发票!C11=0,"",发票!C11) | D20: =IF(发票!D11=0,"",发票!D11) -> #DIV/0! | E20: =IF(发票!E11=0,"",发票!E11)
A21: =IF(发票!A12=0,"",发票!A12) | B21: =IF(发票!B12=0,"",发票!B12) | C21: =IF(发票!C12=0,"",发票!C12) | D21: =IF(发票!D12=0,"",发票!D12) -> #DIV/0! | E21: =IF(发票!E12=0,"",发票!E12)
A22: =IF(发票!A13=0,"",发票!A13) | B22: =IF(发票!B13=0,"",发票!B13) | C22: =IF(发票!C13=0,"",发票!C13) | D22: =IF(发票!D13=0,"",发票!D13) -> #DIV/0! | E22: =IF(发票!E13=0,"",发票!E13)
A23: =IF(发票!A14=0,"",发票!A14) | B23: =IF(发票!B14=0,"",发票!B14) | C23: =IF(发票!C14=0,"",发票!C14) | D23: =IF(发票!D14=0,"",发票!D14) -> #DIV/0! | E23: =IF(发票!E14=0,"",发票!E14)
A24: =IF(发票!A15=0,"",发票!A15) | B24: =IF(发票!B15=0,"",发票!B15) | C24: =IF(发票!C15=0,"",发票!C15) | D24: =IF(发票!D15=0,"",发票!D15) -> #DIV/0! | E24: =IF(发票!E15=0,"",发票!E15)
A25: =IF(发票!A16=0,"",发票!A16) | B25: =IF(发票!B16=0,"",发票!B16) | C25: =IF(发票!C16=0,"",发票!C16) | D25: =IF(发票!D16=0,"",发票!D16) -> #DIV/0! | E25: =IF(发票!E16=0,"",发票!E16)
A26: =IF(发票!A17=0,"",发票!A17) | B26: =IF(发票!B17=0,"",发票!B17) | C26: =IF(发票!C17=0,"",发票!C17) | D26: =IF(发票!D17=0,"",发票!D17) -> #DIV/0! | E26: =IF(发票!E17=0,"",发票!E17)
A27: =IF(发票!A18=0,"",发票!A18) | B27: =IF(发票!B18=0,"",发票!B18) | C27: =IF(发票!C18=0,"",发票!C18) | D27: =IF(发票!D18=0,"",发票!D18) -> #DIV/0! | E27: =IF(发票!E18=0,"",发票!E18)
A28: =IF(发票!A19=0,"",发票!A19) | B28: =IF(发票!B19=0,"",发票!B19) | C28: =IF(发票!C19=0,"",发票!C19) | D28: =IF(发票!D19=0,"",发票!D19) -> #DIV/0! | E28: =IF(发票!E19=0,"",发票!E19)
A29: =IF(发票!A20=0,"",发票!A20) | B29: =IF(发票!B20=0,"",发票!B20) | C29: =IF(发票!C20=0,"",发票!C20) | D29: =IF(发票!D20=0,"",发票!D20) -> #DIV/0! | E29: =IF(发票!E20=0,"",发票!E20)
A30: =IF(发票!A21=0,"",发票!A21) | B30: =IF(发票!B21=0,"",发票!B21) | C30: =IF(发票!C21=0,"",发票!C21) | D30: =IF(发票!D21=0,"",发票!D21) -> #DIV/0! | E30: =IF(发票!E21=0,"",发票!E21)
A31: 合計
A32: 总计（Total）： | C32: =SUM(C18:C30) -> 0 | E32: =SUM(E18:E30) -> 0
A34: (2)包装（Packing): | C34: 按客户要求包装
A35: (3)装运唛头（Shipping Marks): | D35: 无
A36: (4)装运条款（Terms of Shipment): | D36: 按客户要求装运
A37: (5)装运日期（Date of Shipment)： | D37: 2026年1月-2026年12月
A38: (6)装运港（Port of Shipment): | D38: 深圳湾口岸
A39: (7)目的港（Port of Destination): | D39: 香港
A40: (8)分批装运（Transhipment): 允许（ALLOWED)
A41: (9)付款条件（Terms of payment）: 银行转帐
A42: (10)违约责任 Liability for breach of contract （10.1）因卖方交货延迟原因致使买方的出口合同不能履行的，买方有权解除本合同，卖方应赔偿买方因此产生的一切损失。 If by Seller's delay of the production time make the Buyer failed perform the contract ,The Buyer has the right to cancel this contract, the Seller should burden the loss.
A43: （10.2）买方应以最初确认的客观实物的材质和下订单前确认的形状尺寸作为验货的标准，如卖方由于其他非人为的自然因素，无法按时交货，将不属被索赔范围之内。 The inspection of the Buyer should based the standard as which initial model confirmed. If the Seller can not delivery the goods on time due to other non-human natural factors it will be not in the scope of the claim.
A44: (11)本合同共 两 份，自双方代表签字（盖章）之日起生效。
A45: This contract is in 2 copies, effective since being singed by both parties.
...

Sheet 发票
A2: TO:俊興貿易公司 | C2: 深圳兴协贸易有限公司
C3: 深圳市南山区西丽街道麻磡社区奇星工业园5号整套
C4: INVOICE
A6: Port of loading:深圳湾口岸 | C6: ="Invoice No.:"&装箱单!K8 -> Invoice No.: | E6: ="DATE:."&TEXT(装箱单!K7,"yyyy-mm-dd") -> DATE:.1900-01-00
A7: Destination:香港 | C7: ="S\C No."&装箱单!K9 -> S\C No.
A8: DESCRIPTION | B8: BRAND | C8: QUANTITY(Kg) | D8: UNIT PRICE(RMB) | E8: AMOUNT(RMB)
D9: =ROUND(E9/C9,8) -> #DIV/0!
D10: =ROUND(E10/C10,8) -> #DIV/0!
D11: =ROUND(E11/C11,8) -> #DIV/0!
D12: =ROUND(E12/C12,8) -> #DIV/0!
D13: =ROUND(E13/C13,8) -> #DIV/0!
D14: =ROUND(E14/C14,8) -> #DIV/0!
D15: =ROUND(E15/C15,8) -> #DIV/0!
D16: =ROUND(E16/C16,8) -> #DIV/0!
D17: =ROUND(E17/C17,8) -> #DIV/0!
D18: =ROUND(E18/C18,8) -> #DIV/0!
D19: =ROUND(E19/C19,8) -> #DIV/0!
D20: =ROUND(E20/C20,8) -> #DIV/0!
... D22: =ROUND(E22/C22,8) -> #DIV/0!
A23: TOTAL CTNS | B23: =装箱单!D36 -> 1 | C23: =SUM(C9:C22) -> 0 | E23: =SUM(E9:E22) -> 0 | F23: =IF(E23=报关明细表!L27,"",FALSE) -> FALSE | G23: =IF(C23=报关明细表!H27,"",FALSE) -> FALSE

Sheet 装箱单
A1: 深圳兴协贸易有限公司
A2: 深圳市南山区西丽街道麻磡社区奇星工业园5号整套
A5: PACKING LIST
A7: TO: | B7: Chun Hing Trading Co. | G7: DATE: | K7: =报关明细表!A3 -> 0
G8: INVOICE NO.:
G9: CONTRACK NO:
A11: DESCRIPTION | B11: BRAND | C11: DESCRIPTION | D11: Q'TY | F11: N.W(kg) | I11: G.W(kg) | L11: PACKING()
A12: =IF(报关明细表!B3=0,"",报关明细表!B3) -> 美星450碗 | B12: =IF(报关明细表!D3=0,"",报关明细表!D3) | C12: =IFERROR(VLOOKUP(A12,报关明细表!$B$3:$C$25,2,FALSE),"") -> 塑料餐具：碗 | D12: =IFERROR(VLOOKUP(A12,报关明细表!B$3:H$27,4,FALSE),"") -> 1 | F12: =IFERROR(VLOOKUP(A12,报关明细表!B$3:H$27,7,FALSE),"") -> 8.83 | I12: =IFERROR(VLOOKUP(A12,报关明细表!B$3:J$27,9,FALSE),"") -> 9.33 | L12: =IFERROR(VLOOKUP(A12,报关明细表!B$3:F$27,5,FALSE),"") -> 300
A13: =IF(报关明细表!B4=0,"",报关明细表!B4) | B13: =IF(报关明细表!D4=0,"",报关明细表!D4) | C13: =IFERROR(VLOOKUP(A13,报关明细表!$B$3:$C$25,2,FALSE),"") | D13: =IFERROR(VLOOKUP(A13,报关明细表!B$3:H$27,4,FALSE),"") | F13: =IFERROR(VLOOKUP(A13,报关明细表!B$3:H$27,7,FALSE),"") | I13: =IFERROR(VLOOKUP(A13,报关明细表!B$3:J$27,9,FALSE),"") | L13: =IFERROR(VLOOKUP(A13,报关明细表!B$3:F$27,5,FALSE),"")
A14: =IF(报关明细表!B5=0,"",报关明细表!B5) | B14: =IF(报关明细表!D5=0,"",报关明细表!D5) | C14: =IFERROR(VLOOKUP(A14,报关明细表!$B$3:$C$25,2,FALSE),"") | D14: =IFERROR(VLOOKUP(A14,报关明细表!B$3:H$27,4,FALSE),"") | F14: =IFERROR(VLOOKUP(A14,报关明细表!B$3:H$27,7,FALSE),"") | I14: =IFERROR(VLOOKUP(A14,报关明细表!B$3:J$27,9,FALSE),"") | L14: =IFERROR(VLOOKUP(A14,报关明细表!B$3:F$27,5,FALSE),"")
A15: =IF(报关明细表!B6=0,"",报关明细表!B6) | B15: =IF(报关明细表!D6=0,"",报关明细表!D6) | C15: =IFERROR(VLOOKUP(A15,报关明细表!$B$3:$C$25,2,FALSE),"") | D15: =IFERROR(VLOOKUP(A15,报关明细表!B$3:H$27,4,FALSE),"") | F15: =IFERROR(VLOOKUP(A15,报关明细表!B$3:H$27,7,FALSE),"") | I15: =IFERROR(VLOOKUP(A15,报关明细表!B$3:J$27,9,FALSE),"") | L15: =IFERROR(VLOOKUP(A15,报关明细表!B$3:F$27,5,FALSE),"")
A16: =IF(报关明细表!B7=0,"",报关明细表!B7) | B16: =IF(报关明细表!D7=0,"",报关明细表!D7) | C16: =IFERROR(VLOOKUP(A16,报关明细表!$B$3:$C$25,2,FALSE),"") | D16: =IFERROR(VLOOKUP(A16,报关明细表!B$3:H$27,4,FALSE),"") | F16: =IFERROR(VLOOKUP(A16,报关明细表!B$3:H$27,7,FALSE),"") | I16: =IFERROR(VLOOKUP(A16,报关明细表!B$3:J$27,9,FALSE),"") | L16: =IFERROR(VLOOKUP(A16,报关明细表!B$3:F$27,5,FALSE),"")
A17: =IF(报关明细表!B8=0,"",报关明细表!B8) | B17: =IF(报关明细表!D8=0,"",报关明细表!D8) | C17: =IFERROR(VLOOKUP(A17,报关明细表!$B$3:$C$25,2,FALSE),"") | D17: =IFERROR(VLOOKUP(A17,报关明细表!B$3:H$27,4,FALSE),"") | F17: =IFERROR(VLOOKUP(A17,报关明细表!B$3:H$27,7,FALSE),"") | I17: =IFERROR(VLOOKUP(A17,报关明细表!B$3:J$27,9,FALSE),"") | L17: =IFERROR(VLOOKUP(A17,报关明细表!B$3:F$27,5,FALSE),"")
A18: =IF(报关明细表!B9=0,"",报关明细表!B9) | B18: =IF(报关明细表!D9=0,"",报关明细表!D9) | C18: =IFERROR(VLOOKUP(A18,报关明细表!$B$3:$C$25,2,FALSE),"") | D18: =IFERROR(VLOOKUP(A18,报关明细表!B$3:H$27,4,FALSE),"") | F18: =IFERROR(VLOOKUP(A18,报关明细表!B$3:H$27,7,FALSE),"") | I18: =IFERROR(VLOOKUP(A18,报关明细表!B$3:J$27,9,FALSE),"") | L18: =IFERROR(VLOOKUP(A18,报关明细表!B$3:F$27,5,FALSE),"")
A19: =IF(报关明细表!B10=0,"",报关明细表!B10) | B19: =IF(报关明细表!D10=0,"",报关明细表!D10) | C19: =IFERROR(VLOOKUP(A19,报关明细表!$B$3:$C$25,2,FALSE),"") | D19: =IFERROR(VLOOKUP(A19,报关明细表!B$3:H$27,4,FALSE),"") | F19: =IFERROR(VLOOKUP(A19,报关明细表!B$3:H$27,7,FALSE),"") | I19: =IFERROR(VLOOKUP(A19,报关明细表!B$3:J$27,9,FALSE),"") | L19: =IFERROR(VLOOKUP(A19,报关明细表!B$3:F$27,5,FALSE),"")
A20: =IF(报关明细表!B11=0,"",报关明细表!B11) | B20: =IF(报关明细表!D11=0,"",报关明细表!D11) | C20: =IFERROR(VLOOKUP(A20,报关明细表!$B$3:$C$25,2,FALSE),"") | D20: =IFERROR(VLOOKUP(A20,报关明细表!B$3:H$27,4,FALSE),"") | F20: =IFERROR(VLOOKUP(A20,报关明细表!B$3:H$27,7,FALSE),"") | I20: =IFERROR(VLOOKUP(A20,报关明细表!B$3:J$27,9,FALSE),"") | L20: =IFERROR(VLOOKUP(A20,报关明细表!B$3:F$27,5,FALSE),"")
A21: =IF(报关明细表!B12=0,"",报关明细表!B12) | B21: =IF(报关明细表!D12=0,"",报关明细表!D12) | C21: =IFERROR(VLOOKUP(A21,报关明细表!$B$3:$C$25,2,FALSE),"") | D21: =IFERROR(VLOOKUP(A21,报关明细表!B$3:H$27,4,FALSE),"") | F21: =IFERROR(VLOOKUP(A21,报关明细表!B$3:H$27,7,FALSE),"") | I21: =IFERROR(VLOOKUP(A21,报关明细表!B$3:J$27,9,FALSE),"") | L21: =IFERROR(VLOOKUP(A21,报关明细表!B$3:F$27,5,FALSE),"")
A22: =IF(报关明细表!B13=0,"",报关明细表!B13) | B22: =IF(报关明细表!D13=0,"",报关明细表!D13) | C22: =IFERROR(VLOOKUP(A22,报关明细表!$B$3:$C$25,2,FALSE),"") | D22: =IFERROR(VLOOKUP(A22,报关明细表!B$3:H$27,4,FALSE),"") | F22: =IFERROR(VLOOKUP(A22,报关明细表!B$3:H$27,7,FALSE),"") | I22: =IFERROR(VLOOKUP(A22,报关明细表!B$3:J$27,9,FALSE),"") | L22: =IFERROR(VLOOKUP(A22,报关明细表!B$3:F$27,5,FALSE),"")
A23: =IF(报关明细表!B14=0,"",报关明细表!B14) | B23: =IF(报关明细表!D14=0,"",报关明细表!D14) | C23: =IFERROR(VLOOKUP(A23,报关明细表!$B$3:$C$25,2,FALSE),"") | D23: =IFERROR(VLOOKUP(A23,报关明细表!B$3:H$27,4,FALSE),"") | F23: =IFERROR(VLOOKUP(A23,报关明细表!B$3:H$27,7,FALSE),"") | I23: =IFERROR(VLOOKUP(A23,报关明细表!B$3:J$27,9,FALSE),"") | L23: =IFERROR(VLOOKUP(A23,报关明细表!B$3:F$27,5,FALSE),"")
... A33: =IF(报关明细表!B24=0,"",报关明细表!B24) | B33: =IF(报关明细表!D24=0,"",报关明细表!D24) | C33: =IFERROR(VLOOKUP(A33,报关明细表!$B$3:$C$25,2,FALSE),"") | D33: =IFERROR(VLOOKUP(A33,报关明细表!B$3:H$27,4,FALSE),"") | F33: =IFERROR(VLOOKUP(A33,报关明细表!B$3:H$27,7,FALSE),"") | I33: =IFERROR(VLOOKUP(A33,报关明细表!B$3:J$27,9,FALSE),"") | L33: =IFERROR(VLOOKUP(A33,报关明细表!B$3:F$27,5,FALSE),"")
A34: =IF(报关明细表!B25=0,"",报关明细表!B25) | B34: =IF(报关明细表!D25=0,"",报关明细表!D25) | I34: =IFERROR(VLOOKUP(A34,报关明细表!B$3:J$27,9,FALSE),"")
I35: =IFERROR(VLOOKUP(A35,报关明细表!B$3:J$27,9,FALSE),"")
A36: TOTAL | D36: =SUM(D12:D35) -> 1 | E36: CTNS | G36: =SUM(F12:H35) -> 8.83 | H36: kg | J36: =SUM(I12:K35) -> 9.33 | K36: kg

Sheet 报关明细表
A1: 报关出口明细表：
A2: 出货日期 | B2: 产品名称 | C2: 品種 | D2: 品牌 | E2: 数量 | F2: 裝箱數 | G2: 单个净重 | H2: 总净重 | I2: 单个毛重 | J2: 总毛重 | K2: 出口单价（RMB） | L2: 出口金额（RMB） | M2: 供應商 | N2: 發票編號 | O2: 报关单号 | P2: 六联单号
A3: =工作表2!A1 -> 0 | B3: =IF(工作表3!A1=0,"",工作表3!A1) -> 美星450碗 | C3: =IF(工作表3!C1=0,"",工作表3!C1) -> 塑料餐具：碗 | E3: =IF(工作表3!I1=0,"",工作表3!I1) -> 1 | F3: =IF(工作表3!D1=0,"",工作表3!D1) -> 300 | H3: =IF(工作表3!J1=0,"",工作表3!J1) -> 8.83 | J3: =IFERROR(H3+E3/2,"") -> 9.33 | K3: =IFERROR(L3/J3,"") -> 8.7888532 | L3: =IF(工作表3!M1=0,"",工作表3!M1) -> 82 | M3: =IF(工作表3!B1=0,"",工作表3!B1) -> 東莞美星
B4: =IF(工作表3!A2=0,"",工作表3!A2) | C4: =IF(工作表3!C2=0,"",工作表3!C2) | E4: =IF(工作表3!I2=0,"",工作表3!I2) | F4: =IF(工作表3!D2=0,"",工作表3!D2) | H4: =IF(工作表3!J2=0,"",工作表3!J2) | J4: =IFERROR(H4+E4/2,"") | K4: =IFERROR(L4/J4,"") | L4: =IF(工作表3!M2=0,"",工作表3!M2) | M4: =IF(工作表3!B2=0,"",工作表3!B2)
B5: =IF(工作表3!A3=0,"",工作表3!A3) | C5: =IF(工作表3!C3=0,"",工作表3!C3) | E5: =IF(工作表3!I3=0,"",工作表3!I3) | F5: =IF(工作表3!D3=0,"",工作表3!D3) | H5: =IF(工作表3!J3=0,"",工作表3!J3) | J5: =IFERROR(H5+E5/2,"") | K5: =IFERROR(L5/J5,"") | L5: =IF(工作表3!M3=0,"",工作表3!M3) | M5: =IF(工作表3!B3=0,"",工作表3!B3)
B6: =IF(工作表3!A4=0,"",工作表3!A4) | C6: =IF(工作表3!C4=0,"",工作表3!C4) | E6: =IF(工作表3!I4=0,"",工作表3!I4) | F6: =IF(工作表3!D4=0,"",工作表3!D4) | H6: =IF(工作表3!J4=0,"",工作表3!J4) | J6: =IFERROR(H6+E6/2,"") | K6: =IFERROR(L6/J6,"") | L6: =IF(工作表3!M4=0,"",工作表3!M4) | M6: =IF(工作表3!B4=0,"",工作表3!B4)
B7: =IF(工作表3!A5=0,"",工作表3!A5) | C7: =IF(工作表3!C5=0,"",工作表3!C5) | E7: =IF(工作表3!I5=0,"",工作表3!I5) | F7: =IF(工作表3!D5=0,"",工作表3!D5) | H7: =IF(工作表3!J5=0,"",工作表3!J5) | J7: =IFERROR(H7+E7/2,"") | K7: =IFERROR(L7/J7,"") | L7: =IF(工作表3!M5=0,"",工作表3!M5) | M7: =IF(工作表3!B5=0,"",工作表3!B5)
B8: =IF(工作表3!A6=0,"",工作表3!A6) | C8: =IF(工作表3!C6=0,"",工作表3!C6) | E8: =IF(工作表3!I6=0,"",工作表3!I6) | F8: =IF(工作表3!D6=0,"",工作表3!D6) | H8: =IF(工作表3!J6=0,"",工作表3!J6) | J8: =IFERROR(H8+E8/2,"") | K8: =IFERROR(L8/J8,"") | L8: =IF(工作表3!M6=0,"",工作表3!M6) | M8: =IF(工作表3!B6=0,"",工作表3!B6)
B9: =IF(工作表3!A7=0,"",工作表3!A7) | C9: =IF(工作表3!C7=0,"",工作表3!C7) | E9: =IF(工作表3!I7=0,"",工作表3!I7) | F9: =IF(工作表3!D7=0,"",工作表3!D7) | H9: =IF(工作表3!J7=0,"",工作表3!J7) | J9: =IFERROR(H9+E9/2,"") | K9: =IFERROR(L9/J9,"") | L9: =IF(工作表3!M7=0,"",工作表3!M7) | M9: =IF(工作表3!B7=0,"",工作表3!B7)
B10: =IF(工作表3!A8=0,"",工作表3!A8) | C10: =IF(工作表3!C8=0,"",工作表3!C8) | E10: =IF(工作表3!I8=0,"",工作表3!I8) | F10: =IF(工作表3!D8=0,"",工作表3!D8) | H10: =IF(工作表3!J8=0,"",工作表3!J8) | J10: =IFERROR(H10+E10/2,"") | K10: =IFERROR(L10/J10,"") | L10: =IF(工作表3!M8=0,"",工作表3!M8) | M10: =IF(工作表3!B8=0,"",工作表3!B8)
B11: =IF(工作表3!A9=0,"",工作表3!A9) | C11: =IF(工作表3!C9=0,"",工作表3!C9) | E11: =IF(工作表3!I9=0,"",工作表3!I9) | F11: =IF(工作表3!D9=0,"",工作表3!D9) | H11: =IF(工作表3!J9=0,"",工作表3!J9) | J11: =IFERROR(H11+E11/2,"") | K11: =IFERROR(L11/J11,"") | L11: =IF(工作表3!M9=0,"",工作表3!M9) | M11: =IF(工作表3!B9=0,"",工作表3!B9)
B12: =IF(工作表3!A10=0,"",工作表3!A10) | C12: =IF(工作表3!C10=0,"",工作表3!C10) | E12: =IF(工作表3!I10=0,"",工作表3!I10) | F12: =IF(工作表3!D10=0,"",工作表3!D10) | H12: =IF(工作表3!J10=0,"",工作表3!J10) | J12: =IFERROR(H12+E12/2,"") | K12: =IFERROR(L12/J12,"") | L12: =IF(工作表3!M10=0,"",工作表3!M10) | M12: =IF(工作表3!B10=0,"",工作表3!B10)
B13: =IF(工作表3!A11=0,"",工作表3!A11) | C13: =IF(工作表3!C11=0,"",工作表3!C11) | E13: =IF(工作表3!I11=0,"",工作表3!I11) | F13: =IF(工作表3!D11=0,"",工作表3!D11) | H13: =IF(工作表3!J11=0,"",工作表3!J11) | J13: =IFERROR(H13+E13/2,"") | K13: =IFERROR(L13/J13,"") | L13: =IF(工作表3!M11=0,"",工作表3!M11) | M13: =IF(工作表3!B11=0,"",工作表3!B11)
B14: =IF(工作表3!A12=0,"",工作表3!A12) | C14: =IF(工作表3!C12=0,"",工作表3!C12) | E14: =IF(工作表3!I12=0,"",工作表3!I12) | F14: =IF(工作表3!D12=0,"",工作表3!D12) | H14: =IF(工作表3!J12=0,"",工作表3!J12) | J14: =IFERROR(H14+E14/2,"") | K14: =IFERROR(L14/J14,"") | L14: =IF(工作表3!M12=0,"",工作表3!M12) | M14: =IF(工作表3!B12=0,"",工作表3!B12)
B15: =IF(工作表3!A13=0,"",工作表3!A13) | C15: =IF(工作表3!C13=0,"",工作表3!C13) | E15: =IF(工作表3!I13=0,"",工作表3!I13) | F15: =IF(工作表3!D13=0,"",工作表3!D13) | H15: =IF(工作表3!J13=0,"",工作表3!J13) | J15: =IFERROR(H15+E15/2,"") | K15: =IFERROR(L15/J15,"") | L15: =IF(工作表3!M13=0,"",工作表3!M13) | M15: =IF(工作表3!B13=0,"",工作表3!B13)
... B26: =IF(工作表3!A24=0,"",工作表3!A24) | C26: =IF(工作表3!C24=0,"",工作表3!C24) | E26: =IF(工作表3!I24=0,"",工作表3!I24) | F26: =IF(工作表3!D24=0,"",工作表3!D24) | H26: =IF(工作表3!J24=0,"",工作表3!J24) | J26: =IFERROR(H26+E26/2,"") | K26: =IFERROR(L26/J26,"") | L26: =IF(工作表3!M24=0,"",工作表3!M24) | M26: =IF(工作表3!B24=0,"",工作表3!B24)
B27: =IF(工作表3!A25=0,"",工作表3!A25) | C27: =IF(工作表3!C25=0,"",工作表3!C25) | E27: =SUM(E3:E26) -> 1 | F27: =IF(工作表3!D25=0,"",工作表3!D25) | H27: =SUM(H3:H26) -> 8.83 | J27: =SUM(J3:J26) -> 9.33 | L27: =SUM(L3:L26) -> 82 | M27: =IF(工作表3!B25=0,"",工作表3!B25)
A28: =工作表2!B1 -> 0

Sheet 工作表1
A1: 參考
A2: 深圳興明發
A4: 台山本源
A5: 江苏徐洲青青紙制品
A7: 溫洲捷弗瑞材料有限公司
A8: 東莞中央化學
A9: 旺盟(上海)新材料科技有限公司
A10: 東莞美星
A11: 深圳豐園
A12: 汕頭韓盛
A13: 東莞茂盈
A14: 韶能集团绿洲生态(新丰)科技有限公司
A15: 台山長江

Sheet 工作表2
A3: 注塑
B4: 产品型号 | C4: 廠家 | D4: 品種 | E4: 箱數 | F4: 凈重 | G4: 不含稅價 | H4: 稅點 | I4: 廠稅價 | J4: 數量 | K4: 總凈重量 | L4: 總毛重量 | M4: 總廠稅價 | N4: 總報關價
B5: 塑料餐具飯盒
B6: HS1安杯 | C6: 汕頭韓盛 | D6: 塑料餐具：杯 | E6: 2000 | F6: 4 | G6: 66 | H6: 0.07 | I6: =G6*(1+H6) -> 70.62 | K6: =J6*F6 -> 0 | L6: =K6+J6/2 -> 0 | M6: =J6*I6 -> 0 | N6: =M6+J6 -> 0
B7: HS2安杯 | C7: 汕頭韓盛 | D7: 塑料餐具：杯 | E7: 2000 | F7: 4.2 | G7: 56 | H7: 0.07 | I7: =G7*(1+H7) -> 59.92 | K7: =J7*F7 -> 0 | L7: =K7+J7/2 -> 0 | M7: =J7*I7 -> 0 | N7: =M7+J7 -> 0
B8: HS3安杯 | C8: 汕頭韓盛 | D8: 塑料餐具：杯 | E8: 2000 | F8: 5.5 | G8: 78 | H8: 0.07 | I8: =G8*(1+H8) -> 83.46 | K8: =J8*F8 -> 0 | L8: =K8+J8/2 -> 0 | M8: =J8*I8 -> 0 | N8: =M8+J8 -> 0
B9: HS142蓋 | C9: 汕頭韓盛 | D9: 塑料碗蓋 | E9: 600 | F9: 4 | G9: 55 | H9: 0.07 | I9: =G9*(1+H9) -> 58.85 | K9: =J9*F9 -> 0 | L9: =K9+J9/2 -> 0 | M9: =J9*I9 -> 0 | N9: =M9+J9 -> 0
B10: Y1000美式圓碗 | C10: 汕頭韓盛 | D10: 塑料餐具：碗 | E10: 150 | F10: 4.14 | G10: 55 | H10: 0.07 | I10: =G10*(1+H10) -> 58.85 | K10: =J10*F10 -> 0 | L10: =K10+J10/2 -> 0 | M10: =J10*I10 -> 0 | N10: =M10+J10 -> 0
B11: HS500圓盒 | C11: 汕頭韓盛 | D11: 塑料餐具：碗 | E11: 300 | F11: 6.8 | G11: 80 | H11: 0.07 | I11: =G11*(1+H11) -> 85.6 | K11: =J11*F11 -> 0 | L11: =K11+J11/2 -> 0 | M11: =J11*I11 -> 0 | N11: =M11+J11 -> 0
B12: HS500圓碗(底) | C12: 汕頭韓盛 | D12: 塑料餐具：碗 | E12: 600 | F12: 8 | G12: 63 | H12: 0.07 | I12: =G12*(1+H12) -> 67.41 | K12: =J12*F12 -> 0 | L12: =K12+J12/2 -> 0 | M12: =J12*I12 -> 0 | N12: =M12+J12 -> 0
B13: Y1200碗 | C13: 汕頭韓盛 | D13: 塑料餐具：碗 | E13: 150 | F13: 6.03 | G13: 79 | H13: 0.07 | I13: =G13*(1+H13) -> 84.53 | K13: =J13*F13 -> 0 | L13: =K13+J13/2 -> 0 | M13: =J13*I13 -> 0 | N13: =M13+J13 -> 0
B14: Y1350碗 | C14: 汕頭韓盛 | D14: 塑料餐具：碗 | E14: 150 | F14: 6.31 | G14: 83 | H14: 0.07 | I14: =G14*(1+H14) -> 88.81 | K14: =J14*F14 -> 0 | L14: =K14+J14/2 -> 0 | M14: =J14*I14 -> 0 | N14: =M14+J14 -> 0
B15: HS1500碗 | C15: 汕頭韓盛 | D15: 塑料餐具：碗 | E15: 150 | F15: 5.9 | G15: 67 | H15: 0.07 | I15: =G15*(1+H15) -> 71.69 | K15: =J15*F15 -> 0 | L15: =K15+J15/2 -> 0 | M15: =J15*I15 -> 0 | N15: =M15+J15 -> 0
B16: HS1750碗 | C16: 汕頭韓盛 | D16: 塑料餐具：碗 | E16: 150 | F16: 6.37 | G16: 81 | H16: 0.07 | I16: =G16*(1+H16) -> 86.67 | K16: =J16*F16 -> 0 | L16: =K16+J16/2 -> 0 | M16: =J16*I16 -> 0 | N16: =M16+J16 -> 0
B17: HS1000+ | C17: 汕頭韓盛 | D17: 塑料餐具：飯盒 | E17: 300 | F17: 5.8 | G17: 68 | H17: 0.07 | I17: =G17*(1+H17) -> 72.76 | K17: =J17*F17 -> 0 | L17: =K17+J17/2 -> 0 | M17: =J17*I17 -> 0 | N17: =M17+J17 -> 0
... B21: Hs2000美式 | C21: 汕頭韓盛 | D21: 塑料餐具：飯盒 | E21: 150 | F21: 7.05 | G21: 90 | H21: 0.07 | I21: =G21*(1+H21) -> 96.3 | K21: =J21*F21 -> 0 | L21: =K21+J21/2 -> 0 | M21: =J21*I21 -> 0 | N21: =M21+J21 -> 0
B22: Hs2000美式底 | C22: 汕頭韓盛 | D22: 塑料餐具：飯盒 | E22: 150 | K22: =J22*F22 -> 0 | L22: =K22+J22/2 -> 0 | M22: =J22*I22 -> 0 | N22: =M22+J22 -> 0
B23: HS內格 | C23: 汕頭韓盛 | D23: 塑料餐具：碟 | E23: 300 | F23: 3.96 | G23: 59 | H23: 0.07 | I23: =G23*(1+H23) -> 63.13 | K23: =J23*F23 -> 0 | L23: =K23+J23/2 -> 0 | M23: =J23*I23 -> 0 | N23: =M23+J23 -> 0
B24: HS三格 | C24: 汕頭韓盛 | D24: 塑料餐具：飯盒 | E24: 150 | F24: 6.46 | G24: 83 | H24: 0.07 | I24: =G24*(1+H24) -> 88.81 | K24: =J24*F24 -> 0 | L24: =K24+J24/2 -> 0 | M24: =J24*I24 -> 0 | N24: =M24+J24 -> 0
B25: HS三格圓 | C25: 汕頭韓盛 | D25: 塑料餐具：飯盒 | E25: 150 | F25: 6.11 | G25: 78 | H25: 0.07 | I25: =G25*(1+H25) -> 83.46 | K25: =J25*F25 -> 0 | L25: =K25+J25/2 -> 0 | M25: =J25*I25 -> 0 | N25: =M25+J25 -> 0
B26: HS四格方 | C26: 汕頭韓盛 | D26: 塑料餐具：飯盒 | E26: 150 | F26: 6.68 | G26: 85 | H26: 0.07 | I26: =G26*(1+H26) -> 90.95 | K26: =J26*F26 -> 0 | L26: =K26+J26/2 -> 0 | M26: =J26*I26 -> 0 | N26: =M26+J26 -> 0
B27: HS2500盆 | C27: 汕頭韓盛 | D27: 塑料餐具：碗 | E27: 150 | F27: 5.34 | G27: 78 | H27: 0.07 | I27: =G27*(1+H27) -> 83.46 | K27: =J27*F27 -> 0 | L27: =K27+J27/2 -> 0 | M27: =J27*I27 -> 0 | N27: =M27+J27 -> 0
A28: 改東莞出 | B28: 快快樂1000美式 | C28: 東莞茂盈 | D28: 塑料餐具：飯盒 | E28: 150 | F28: 5.5 | G28: 77 | H28: 0.11 | I28: =G28*(1+H28) -> 85.47 | K28: =J28*F28 -> 0 | L28: =K28+J28/2 -> 0 | M28: =J28*I28 -> 0 | N28: =M28+J28 -> 0
A29: 改東莞出 | B29: 快快樂1200美式 | C29: 東莞茂盈 | D29: 塑料餐具：飯盒 | E29: 150 | F29: 7 | G29: 81 | H29: 0.11 | I29: =G29*(1+H29) -> 89.91 | K29: =J29*F29 -> 0 | L29: =K29+J29/2 -> 0 | M29: =J29*I29 -> 0 | N29: =M29+J29 -> 0
A30: 改東莞出 | B30: 快快樂1000碗 | C30: 東莞茂盈 | D30: 塑料餐具：碗 | E30: 150 | F30: 7 | H30: 0.11 | I30: 89.91 | K30: =J30*F30 -> 0 | L30: =K30+J30/2 -> 0 | M30: =J30*I30 -> 0 | N30: =M30+J30 -> 0
B31: 容海500 | C31: 深圳興明發 | D31: 塑料餐具：飯盒 | E31: 300 | F31: 4 | G31: 55 | H31: 0.08 | I31: =G31*(1+H31) -> 59.4 | K31: =J31*F31 -> 0 | L31: =K31+J31/2 -> 0 | M31: =J31*I31 -> 0 | N31: =M31+J31 -> 0
B32: 興明發500底 | C32: 深圳興明發 | D32: 塑料餐具：飯盒 | E32: 600 | F32: 7 | G32: 70 | H32: 0.08 | I32: =G32*(1+H32) -> 75.6 | K32: =J32*F32 -> 0 | L32: =K32+J32/2 -> 0 | M32: =J32*I32 -> 0 | N32: =M32+J32 -> 0
B33: 興明發1250碗 | C33: 深圳興明發 | D33: 塑料餐具：碗 | E33: 150 | F33: 6 | G33: 66 | H33: 0.08 | I33: =G33*(1+H33) -> 71.28 | K33: =J33*F33 -> 0 | L33: =K33+J33/2 -> 0 | M33: =J33*I33 -> 0 | N33: =M33+J33 -> 0
B34: 興明發1250黑碗 | C34: 深圳興明發 | D34: 塑料餐具：碗 | E34: 150 | F34: 6 | G34: 68 | H34: 0.08 | I34: =G34*(1+H34) -> 73.44 | K34: =J34*F34 -> 0 | L34: =K34+J34/2 -> 0 | M34: =J34*I34 -> 0 | N34: =M34+J34 -> 0
B35: 興年華999黑碗 | C35: 深圳興明發 | D35: 塑料餐具：碗 | E35: 600 | F35: 8 | G35: 108 | H35: 0.08 | I35: =G35*(1+H35) -> 116.64 | K35: =J35*F35 -> 0 | L35: =K35+J35/2 -> 0 | M35: =J35*I35 -> 0 | N35: =M35+J35 -> 0
B36: 興年華1000碗 | C36: 深圳興明發 | D36: 塑料餐具：碗 | E36: 600 | F36: 8 | G36: 117 | H36: 0.08 | I36: =G36*(1+H36) -> 126.36 | K36: =J36*F36 -> 0 | L36: =K36+J36/2 -> 0 | M36: =J36*I36 -> 0 | N36: =M36+J36 -> 0
B37: 興年華142蓋 | C37: 深圳興明發 | D37: 塑料碗蓋 | E37: 600 | F37: 3.7 | G37: 52 | H37: 0.08 | I37: =G37*(1+H37) -> 56.16 | K37: =J37*F37 -> 0 | L37: =K37+J37/2 -> 0 | M37: =J37*I37 -> 0 | N37: =M37+J37 -> 0
B38: 興年華1500美式 | C38: 深圳興明發 | D38: 塑料餐具：飯盒 | E38: 150 | F38: 7 | G38: 69 | H38: 0.08 | I38: =G38*(1+H38) -> 74.52 | K38: =J38*F38 -> 0 | L38: =K38+J38/2 -> 0 | M38: =J38*I38 -> 0 | N38: =M38+J38 -> 0
B39: 騰輝1200 | C39: 深圳興明發 | D39: 塑料餐具：飯盒 | E39: 150 | F39: 7 | G39: 69 | H39: 0.08 | I39: =G39*(1+H39) -> 74.52 | K39: =J39*F39 -> 0 | L39: =K39+J39/2 -> 0 | M39: =J39*I39 -> 0 | N39: =M39+J39 -> 0
B40: WDK500 | C40: 東莞茂盈 | D40: 塑料餐具：飯盒 | E40: 300 | F40: 4.9 | G40: 68 | H40: 0.11 | I40: =G40*(1+H40) -> 75.48 | K40: =J40*F40 -> 0 | L40: =K40+J40/2 -> 0 | M40: =J40*I40 -> 0 | N40: =M40+J40 -> 0
B41: WDK650 | C41: 東莞茂盈 | D41: 塑料餐具：飯盒 | E41: 300 | F41: 5.5 | G41: 76 | H41: 0.11 | I41: =G41*(1+H41) -> 84.36 | K41: =J41*F41 -> 0 | L41: =K41+J41/2 -> 0 | M41: =J41*I41 -> 0 | N41: =M41+J41 -> 0
B42: WDK750 | C42: 東莞茂盈 | D42: 塑料餐具：飯盒 | E42: 300 | F42: 6 | G42: 79 | H42: 0.11 | I42: =G42*(1+H42) -> 87.69 | K42: =J42*F42 -> 0 | L42: =K42+J42/2 -> 0 | M42: =J42*I42 -> 0 | N42: =M42+J42 -> 0
B43: WDK1000 | C43: 東莞茂盈 | D43: 塑料餐具：飯盒 | E43: 300 | F43: 7 | G43: 86 | H43: 0.11 | I43: =G43*(1+H43) -> 95.46 | K43: =J43*F43 -> 0 | L43: =K43+J43/2 -> 0 | M43: =J43*I43 -> 0 | N43: =M43+J43 -> 0
B44: 美星三格盒 | C44: 東莞美星 | D44: 塑料餐具：飯盒 | E44: 200 | F44: 11.8 | G44: =I44/(1+H44) -> 119.81132 | H44: 0.06 | I44: 127 | K44: =J44*F44 -> 0 | L44: =K44+J44/2 -> 0 | M44: =J44*I44 -> 0 | N44: =M44+J44 -> 0
B45: 美星750盒 | C45: 東莞美星 | D45: 塑料餐具：飯盒 | E45: 300 | F45: 10.5 | G45: =I45/(1+H45) -> 113.20755 | H45: 0.06 | I45: 120 | K45: =J45*F45 -> 0 | L45: =K45+J45/2 -> 0 | M45: =J45*I45 -> 0 | N45: =M45+J45 -> 0
...

Sheet 工作表3
A1: {=_xlfn._xlws.FILTER(工作表2!B6:N216,工作表2!N6:N216>0,"")} -> 美星450碗 | B1: 東莞美星 | C1: 塑料餐具：碗 | D1: 300 | E1: 8.83 | F1: 76.415094 | G1: 0.06 | H1: 81 | I1: 1 | J1: 8.83 | K1: 9.33 | L1: 81 | M1: 82
